{"errorMessage": "(2003, \"Can't connect to MySQL server on 'mysql-db.curs4g4yygzv.us-east-1.rds.amazonaws.com:3306' ([Errno -2] Name or service not known)\")", "errorType": "OperationalError", "stackTrace": ["  File \"/var/lang/lib/python3.8/imp.py\", line 234, in load_module\n    return load_source(name, filename, file)\n", "  File \"/var/lang/lib/python3.8/imp.py\", line 171, in load_source\n    module = _load(spec)\n", "  File \"<frozen importlib._bootstrap>\", line 702, in _load\n", "  File \"<frozen importlib._bootstrap>\", line 671, in _load_unlocked\n", "  File \"<frozen importlib._bootstrap_external>\", line 843, in exec_module\n", "  File \"<frozen importlib._bootstrap>\", line 219, in _call_with_frames_removed\n", "  File \"/var/task/handler.py\", line 7, in <module>\n    rds_conn = pymysql.connect(\n", "  File \"/var/task/pymysql/connections.py\", line 361, in __init__\n    self.connect()\n", "  File \"/var/task/pymysql/connections.py\", line 716, in connect\n    raise exc\n"]}